<?xml version="1.0" encoding="utf-8"?>
<!-- This URDF was automatically created by SolidWorks to URDF Exporter! Originally created by Stephen Brawner (brawner@gmail.com) 
     Commit Version: 1.6.0-4-g7f85cfe  Build Version: 1.6.7995.38578
     For more information, please see http://wiki.ros.org/sw_urdf_exporter -->
<robot
  name="finger_mujoco">
  <mujoco>
    <compiler meshdir="meshes/"
              balanceinertia="true"
              strippath="false"/>
  </mujoco>
  <link
    name="palm_link">
    <inertial>
      <origin
        xyz="3.095E-05 -0.018207 0.055563"
        rpy="0 0 0" />
      <mass
        value="0.03804" />
      <inertia
        ixx="3.3736E-05"
        ixy="1.4396E-08"
        ixz="-1.8165E-08"
        iyy="3.0294E-05"
        iyz="-4.5681E-07"
        izz="5.8025E-06" />
    </inertial>
    <visual>
      <origin
        xyz="0 0 0"
        rpy="0 0 0" />
      <geometry>
        <mesh
          filename="palm_link.STL" />
      </geometry>
      <material
        name="">
        <color
          rgba="0.79216 0.81961 0.93333 1" />
      </material>
    </visual>
    <collision>
      <origin
        xyz="0 0 0"
        rpy="0 0 0" />
      <geometry>
        <mesh
          filename="palm_link.STL" />
      </geometry>
    </collision>
  </link>
  <link
    name="servo_pulley_link">
    <inertial>
      <origin
        xyz="1.7347E-18 0.0033461 3.4694E-18"
        rpy="0 0 0" />
      <mass
        value="0.00064912" />
      <inertia
        ixx="1.1532E-08"
        ixy="8.4169E-25"
        ixz="2.0525E-10"
        iyy="1.7526E-08"
        iyz="-1.34E-24"
        izz="1.1469E-08" />
    </inertial>
    <visual>
      <origin
        xyz="0 0 0"
        rpy="0 0 0" />
      <geometry>
        <mesh
          filename="servo_pulley_link.STL" />
      </geometry>
      <material
        name="">
        <color
          rgba="1 1 1 1" />
      </material>
    </visual>
    <collision>
      <origin
        xyz="0 0 0"
        rpy="0 0 0" />
      <geometry>
        <mesh
          filename="servo_pulley_link.STL" />
      </geometry>
    </collision>
  </link>
  <joint
    name="joint_servo"
    type="continuous">
    <origin
      xyz="0.00010005 -0.0199 0.038"
      rpy="1.5708 0 0.41034" />
    <parent
      link="palm_link" />
    <child
      link="servo_pulley_link" />
    <axis
      xyz="0 1 0" />
    <limit
      lower="-1.57"
      upper="1.57"
      effort="0"
      velocity="0" />
  </joint>
  <link
    name="motor_pulley_link">
    <inertial>
      <origin
        xyz="-0.00028931 0.0095592 -0.00028355"
        rpy="0 0 0" />
      <mass
        value="0.0053624" />
      <inertia
        ixx="2.4087E-07"
        ixy="-1.1788E-08"
        ixz="-1.6646E-08"
        iyy="2.5237E-07"
        iyz="-1.1554E-08"
        izz="2.4154E-07" />
    </inertial>
    <visual>
      <origin
        xyz="0 0 0"
        rpy="0 0 0" />
      <geometry>
        <mesh
          filename="motor_pulley_link.STL" />
      </geometry>
      <material
        name="">
        <color
          rgba="1 1 1 1" />
      </material>
    </visual>
    <collision>
      <origin
        xyz="0 0 0"
        rpy="0 0 0" />
      <geometry>
        <mesh
          filename="motor_pulley_link.STL" />
      </geometry>
    </collision>
  </link>
  <joint
    name="joint_motor"
    type="continuous">
    <origin
      xyz="0 -0.0065 0.0575"
      rpy="3.1416 0.012337 0" />
    <parent
      link="palm_link" />
    <child
      link="motor_pulley_link" />
    <axis
      xyz="0 1 0" />
    <limit
      lower="-3.12"
      upper="3.12"
      effort="0"
      velocity="0" />
  </joint>
  <link
    name="phalanx1_link1_abd">
    <inertial>
      <origin
        xyz="-5.9722E-05 -0.0084809 -0.0081966"
        rpy="0 0 0" />
      <mass
        value="0.0025141" />
      <inertia
        ixx="6.0121E-08"
        ixy="3.0279E-10"
        ixz="-2.3517E-09"
        iyy="6.5393E-08"
        iyz="1.1194E-09"
        izz="9.328E-08" />
    </inertial>
    <visual>
      <origin
        xyz="0 0 0"
        rpy="0 0 0" />
      <geometry>
        <mesh
          filename="phalanx1_link1_abd.STL" />
      </geometry>
      <material
        name="">
        <color
          rgba="1 1 1 1" />
      </material>
    </visual>
    <collision>
      <origin
        xyz="0 0 0"
        rpy="0 0 0" />
      <geometry>
        <mesh
          filename="phalanx1_link1_abd.STL" />
      </geometry>
    </collision>
  </link>
  <joint
    name="joint0_abd"
    type="revolute">
    <origin
      xyz="0.00025 -0.0054079 0.10695"
      rpy="3.1416 0 3.1416" />
    <parent
      link="palm_link" />
    <child
      link="phalanx1_link1_abd" />
    <axis
      xyz="0 1 0" />
    <limit
      lower="-0.7"
      upper="0.7"
      effort="0"
      velocity="0" />
  </joint>
  <link
    name="phalanx_link1_prx">
    <inertial>
      <origin
        xyz="0.0031611 0.00033176 -0.0057507"
        rpy="0 0 0" />
      <mass
        value="0.0059145" />
      <inertia
        ixx="3.5462E-07"
        ixy="1.5123E-10"
        ixz="2.5381E-09"
        iyy="3.7855E-07"
        iyz="3.2223E-10"
        izz="5.0077E-07" />
    </inertial>
    <visual>
      <origin
        xyz="0 0 0"
        rpy="0 0 0" />
      <geometry>
        <mesh
          filename="phalanx_link1_prx.STL" />
      </geometry>
      <material
        name="">
        <color
          rgba="1 1 1 1" />
      </material>
    </visual>
    <collision>
      <origin
        xyz="0 0 0"
        rpy="0 0 0" />
      <geometry>
        <mesh
          filename="phalanx_link1_prx.STL" />
      </geometry>
    </collision>
  </link>
  <joint
    name="joint1_prx"
    type="revolute">
    <origin
      xyz="0 -0.0085921 -0.01705"
      rpy="0 0 1.5708" />
    <parent
      link="phalanx1_link1_abd" />
    <child
      link="phalanx_link1_prx" />
    <axis
      xyz="0 1 0" />
    <limit
      lower="-0.7"
      upper="0.7"
      effort="0"
      velocity="0" />
  </joint>
  <link
    name="phalanx1_link2_prx">
    <inertial>
      <origin
        xyz="0.00029466 0.00025493 -0.0078726"
        rpy="0 0 0" />
      <mass
        value="0.002014" />
      <inertia
        ixx="4.8364E-08"
        ixy="1.488E-10"
        ixz="1.2553E-10"
        iyy="3.3878E-08"
        iyz="1.3325E-09"
        izz="5.9571E-08" />
    </inertial>
    <visual>
      <origin
        xyz="0 0 0"
        rpy="0 0 0" />
      <geometry>
        <mesh
          filename="phalanx1_link2_prx.STL" />
      </geometry>
      <material
        name="">
        <color
          rgba="1 1 1 1" />
      </material>
    </visual>
    <collision>
      <origin
        xyz="0 0 0"
        rpy="0 0 0" />
      <geometry>
        <mesh
          filename="phalanx1_link2_prx.STL" />
      </geometry>
    </collision>
  </link>
  <joint
    name="joint2_prx"
    type="revolute">
    <origin
      xyz="0 0 -0.0114"
      rpy="0 0 0" />
    <parent
      link="phalanx_link1_prx" />
    <child
      link="phalanx1_link2_prx" />
    <axis
      xyz="0 1 0" />
    <limit
      lower="-0.7"
      upper="0.7"
      effort="0"
      velocity="0" />
  </joint>
  <link
    name="phalanx_link1_int">
    <inertial>
      <origin
        xyz="0.00043592 0.00033932 -0.005629"
        rpy="0 0 0" />
      <mass
        value="0.0015511" />
      <inertia
        ixx="4.1412E-08"
        ixy="1.0185E-09"
        ixz="7.2498E-10"
        iyy="3.6368E-08"
        iyz="3.0891E-10"
        izz="5.6225E-08" />
    </inertial>
    <visual>
      <origin
        xyz="0 0 0"
        rpy="0 0 0" />
      <geometry>
        <mesh
          filename="phalanx_link1_int.STL" />
      </geometry>
      <material
        name="">
        <color
          rgba="1 1 1 1" />
      </material>
    </visual>
    <collision>
      <origin
        xyz="0 0 0"
        rpy="0 0 0" />
      <geometry>
        <mesh
          filename="phalanx_link1_int.STL" />
      </geometry>
    </collision>
  </link>
  <joint
    name="joint3_int"
    type="revolute">
    <origin
      xyz="0 0 -0.01555"
      rpy="0 0 0" />
    <parent
      link="phalanx1_link2_prx" />
    <child
      link="phalanx_link1_int" />
    <axis
      xyz="0 1 0" />
    <limit
      lower="-0.7"
      upper="0.7"
      effort="0"
      velocity="0" />
  </joint>
  <link
    name="phalanx_link2_int">
    <inertial>
      <origin
        xyz="0.0033404 0.00030416 -0.0057723"
        rpy="0 0 0" />
      <mass
        value="0.0057585" />
      <inertia
        ixx="3.4985E-07"
        ixy="-1.1057E-09"
        ixz="1.622E-09"
        iyy="3.7085E-07"
        iyz="6.9298E-10"
        izz="4.8937E-07" />
    </inertial>
    <visual>
      <origin
        xyz="0 0 0"
        rpy="0 0 0" />
      <geometry>
        <mesh
          filename="phalanx_link2_int.STL" />
      </geometry>
      <material
        name="">
        <color
          rgba="1 1 1 1" />
      </material>
    </visual>
    <collision>
      <origin
        xyz="0 0 0"
        rpy="0 0 0" />
      <geometry>
        <mesh
          filename="phalanx_link2_int.STL" />
      </geometry>
    </collision>
  </link>
  <joint
    name="joint4_int"
    type="revolute">
    <origin
      xyz="0 0 -0.0114"
      rpy="0 0 0" />
    <parent
      link="phalanx_link1_int" />
    <child
      link="phalanx_link2_int" />
    <axis
      xyz="0 1 0" />
    <limit
      lower="-0.7"
      upper="0.7"
      effort="0"
      velocity="0" />
  </joint>
  <link
    name="phalanx_link3_int">
    <inertial>
      <origin
        xyz="9.7987E-05 -0.00025512 0.0076047"
        rpy="0 0 0" />
      <mass
        value="0.0019386" />
      <inertia
        ixx="4.7362E-08"
        ixy="-1.0401E-10"
        ixz="6.6045E-10"
        iyy="3.3402E-08"
        iyz="1.2609E-09"
        izz="6.1046E-08" />
    </inertial>
    <visual>
      <origin
        xyz="0 0 0"
        rpy="0 0 0" />
      <geometry>
        <mesh
          filename="phalanx_link3_int.STL" />
      </geometry>
      <material
        name="">
        <color
          rgba="1 1 1 1" />
      </material>
    </visual>
    <collision>
      <origin
        xyz="0 0 0"
        rpy="0 0 0" />
      <geometry>
        <mesh
          filename="phalanx_link3_int.STL" />
      </geometry>
    </collision>
  </link>
  <joint
    name="joint5_int"
    type="revolute">
    <origin
      xyz="0 0 -0.0114"
      rpy="3.1416 0 0" />
    <parent
      link="phalanx_link2_int" />
    <child
      link="phalanx_link3_int" />
    <axis
      xyz="0 1 0" />
    <limit
      lower="-0.7"
      upper="0.7"
      effort="0"
      velocity="0" />
  </joint>
  <link
    name="phalanx_link1_dis">
    <inertial>
      <origin
        xyz="-0.00010858 0.00025287 -0.0094074"
        rpy="0 0 0" />
      <mass
        value="0.0023104" />
      <inertia
        ixx="9.5883E-08"
        ixy="4.6265E-11"
        ixz="-5.4334E-10"
        iyy="9.9427E-08"
        iyz="-1.2984E-11"
        izz="7.7015E-08" />
    </inertial>
    <visual>
      <origin
        xyz="0 0 0"
        rpy="0 0 0" />
      <geometry>
        <mesh
          filename="phalanx_link1_dis.STL" />
      </geometry>
      <material
        name="">
        <color
          rgba="1 1 1 1" />
      </material>
    </visual>
    <collision>
      <origin
        xyz="0 0 0"
        rpy="0 0 0" />
      <geometry>
        <mesh
          filename="phalanx_link1_dis.STL" />
      </geometry>
    </collision>
  </link>
  <joint
    name="joint6_dis"
    type="revolute">
    <origin
      xyz="0 0 0.0149"
      rpy="3.1416 0 0" />
    <parent
      link="phalanx_link3_int" />
    <child
      link="phalanx_link1_dis" />
    <axis
      xyz="0 1 0" />
    <limit
      lower="-0.7"
      upper="0.7"
      effort="0"
      velocity="0" />
  </joint>
</robot>